Workbook

Sheet studios
A1: _RowNum | B1: studio_ID | C1: studioname | D1: contact | E1: fname | F1: surname | G1: email | H1: mobile | I1: city | J1: countryID | K1: instagram | L1: pincode | M1: datecreated | N1: lastupdated | O1: ipaddress | P1: sessionID | Q1: secureno | R1: duplicates | S1: bulk_link | T1: bulk_uploaded | U1: filler
A2: 0 | B2: 2 | C2: ARISTO DANCE | E2: Luīza | F2: ŠEPEĻEVA | G2: luiza.sepeleva@gmail.com | H2: +371 27903343 | I2: M&#256;RUPE | J2: 119 | K2: dsaristo_lv | L2: 309809 | M2: 44956.391 | N2: 45793.84 | O2: 80.89.77.147 | P2: 183465237 | Q2: 309809183465237 | R2: ARISTO DANCE luiza.sepeleva@gmail.com309809 | T2: 0
A3: 1 | B3: 3 | C3: BAZA DANCE COMPANY | E3: Marija | F3: SMOLENKOVA | G3: maria.smolenkova95@gmail.com | H3: +371 26785285 | I3: RĪGA | J3: 119 | K3: @maria.smolenkova | L3: 414484 | M3: 44956.488 | N3: 45934.495 | O3: 83.99.244.52 | P3: 263239188 | Q3: 414484263239188 | R3: BAZA DANCE COMPANYmaria.smolenkova95@gmail.com414484 | S3: https://upcdn.io/W23MT4R/raw/uploads/2025/10/04/4jTomEFp6d-MADNESS%20TEAM.docx | T3: 1
A4: 2 | B4: 4 | C4: ZFORCE | E4: Svetlana | F4: KOROLE | G4: lanakor@inbox.lv | H4: +371 29684055 | I4: RĪGA | J4: 119 | L4: 308129 | M4: 44956.518 | N4: 45216.341 | O4: 90.139.255.91 | P4: 868943437 | Q4: 308129868943437 | R4: ZFORCElanakor@inbox.lv308129 | T4: 0
A5: 3 | B5: 5 | C5: MUSTAMÄE HUVIKOOL ESTRAADITANTSUKOOL PEPPY DANCE | E5: Jekaterina | F5: ILNITSKAJA | G5: jekaterina.muravljova@gmail.com | H5: +372 53663366 | I5: TALLINN | J5: 69 | L5: 683174 | M5: 44960.312 | N5: 44970.456 | O5: 80.235.84.93 | P5: 239718100 | Q5: 683174239718100 | R5: MUSTAMÄE HUVIKOOL ESTRAADITANTSUKOOL PEPPY DANCEjekaterina.muravljova@gmail.com683174 | T5: 0
A6: 4 | B6: 6 | C6: TANSSIVA PORVOO | E6: Mia | F6: KOPONEN | G6: tanssivaporvoo@gmail.com | H6: +358 407313175 | I6: PORVOO | J6: 75 | K6: tanssivaporvoo | L6: 412239 | M6: 44960.461 | N6: 44960.651 | O6: 77.105.123.85 | P6: 614487791 | Q6: 412239614487791 | R6: TANSSIVA PORVOOtanssivaporvoo@gmail.com412239 | T6: 0
A7: 5 | B7: 7 | C7: 1ST CUT DANCE BASE | E7: Jenny | F7: WOLKANOWSKI | G7: j.wolkanowski@1stcut.de | H7: +49 17621209594 | I7: GIESSEN | J7: 82 | L7: 668049 | M7: 44961.436 | N7: 44961.436 | O7: 77.12.113.111 | P7: 425241107 | Q7: 668049425241107 | R7: 1ST CUT DANCE BASEj.wolkanowski@1stcut.de668049 | T7: 0
A8: 6 | B8: 8 | C8: CHOREOGRAPHY STUDIO INKARELIS | E8: Mindaugas | F8: PADAGAS | G8: padagasmindaugas@gmail.com | H8: +370 65481824 | I8: KLAIPEDA | J8: 125 | L8: 374121 | M8: 44961.758 | N8: 44977.917 | O8: 90.139.19.127 | P8: 871366362 | Q8: 374121871366362 | R8: CHOREOGRAPHY STUDIO INKARELISpadagasmindaugas@gmail.com374121 | T8: 0
A9: 7 | B9: 9 | C9: DE ARTE | E9: Tatjana | F9: ABROSIMOVA | G9: tatjana.abrosimova@inbox.lv | H9: +371 29546247 | I9: RĪGA | J9: 119 | L9: 350201 | M9: 44963.302 | N9: 44963.308 | O9: 87.110.144.140 | P9: 178790097 | Q9: 350201178790097 | R9: DE ARTEtatjana.abrosimova@inbox.lv350201 | T9: 0
A10: 8 | B10: 10 | C10: DREAM DANCE STUDIO | E10: Darja | F10: STOJANE | G10: dancestudiodream@gmail.com | H10: +371 26724214 | I10: RĪGA | J10: 119 | L10: 267242 | M10: 44963.496 | N10: 45684.375 | O10: 90.139.19.127 | P10: 827049846 | Q10: 267242827049846 | R10: DREAM DANCE STUDIOdancestudiodream@gmail.com267242 | T10: 0
A11: 9 | B11: 11 | C11: DANCE STUDIO STARMIX | E11: Megija | F11: UPESJOZUPA | G11: mupesjozupa@gmail.com | H11: +371 26279720 | I11: TALSI | J11: 119 | L11: 424390 | M11: 44963.745 | N11: 44963.748 | O11: 80.89.77.255 | P11: 127265063 | Q11: 424390127265063 | R11: DANCE STUDIO STARMIXmupesjozupa@gmail.com424390 | T11: 0
A12: 10 | B12: 12 | C12: VOU DANCE GROUP | E12: Elle | F12: AGAR | G12: elle.agar.001@gmail.com | H12: +372 56822312 | I12: MULGI VALD | J12: 69 | L12: 818245 | M12: 44963.786 | N12: 44980.327 | O12: 90.190.141.84 | P12: 843055957 | Q12: 818245843055957 | R12: VOU DANCE GROUPelle.agar.001@gmail.com818245 | T12: 0
A13: 11 | B13: 13 | C13: MS DANCE GROUP | E13: Maria | F13: SALIENKO-ZAHAROVA | G13: marija.salijenko@gmail.com | H13: 29594128 | I13: RĪGA | J13: 119 | L13: 140197 | M13: 44964.309 | N13: 45568.419 | O13: 212.142.115.164 | P13: 193643433 | Q13: 140197193643433 | R13: MS DANCE GROUPmarija.salijenko@gmail.com140197 | T13: 0
A14: 12 | B14: 14 | C14: TEIXMA DANCE | E14: Teiksma | F14: ZIEMELE | G14: teixma@teixma.lv | H14: +371 23071100 | I14: OGRE - LIELVĀRDE - IKŠĶILE | J14: 119 | L14: 642925 | M14: 44964.397 | N14: 45687.419 | O14: 62.85.33.124 | P14: 936493350 | Q14: 642925936493350 | R14: TEIXMA DANCEteixma@teixma.lv642925 | T14: 0
A15: 13 | B15: 15 | C15: HOREOGRĀFISKAIS ANSAMBLIS KOLORĪTS | E15: Jolanta | F15: ROSLOVA | G15: jolja24@inbox.lv | H15: +371 29120948 | I15: RĒZEKNE | J15: 119 | L15: 374401 | M15: 44964.483 | N15: 44970.354 | O15: 81.198.91.5 | P15: 206435845 | Q15: 374401206435845 | R15: HOREOGRĀFISKAIS ANSAMBLIS KOLORĪTSjolja24@inbox.lv374401 | T15: 0
A16: 14 | B16: 16 | C16: SMILTE | E16: Ramona | F16: VALIUTE-ZUKAUSKIENE | G16: smilte.dance@gmail.com | H16: +370 60966577 | I16: KLAIPEDA | J16: 125 | L16: 984595 | M16: 44964.495 | N16: 44990.852 | O16: 86.100.21.26 | P16: 278715968 | Q16: 984595278715968 | R16: SMILTEsmilte.dance@gmail.com984595 | T16: 0
A17: 15 | B17: 17 | C17: CIARA DANCE SCHOOL | E17: Carolin | F17: ARNOLD | G17: info@tantsukoolciara.ee | H17: +372 5257153 | I17: TARTU | J17: 69 | K17: ciaratantsukool | L17: 246429 | M17: 44964.823 | N17: 44981.789 | O17: 90.191.83.114 | P17: 843891425 | Q17: 246429843891425 | R17: CIARA DANCE SCHOOLinfo@tantsukoolciara.ee246429 | T17: 0
A18: 16 | B18: 18 | C18: DANCE STUDIO DIAMOND | E18: Tatjana | F18: ČILIKINA | G18: caliente85@inbox.lv | H18: +371 22324147 | I18: RĪGA | J18: 119 | L18: 332111 | M18: 44965.454 | N18: 45001.468 | O18: 90.139.19.127 | P18: 528154260 | Q18: 332111528154260 | R18: DANCE STUDIO DIAMONDcaliente85@inbox.lv332111 | T18: 0
A19: 17 | B19: 19 | C19: DEJU STUDIJA 27 | E19: Kristine | F19: OLEKSENKO | G19: dejustudija27@gmail.com | H19: +371 26025883 | I19: RĪGA | J19: 119 | L19: 270391 | M19: 44968.416 | N19: 45688.88 | O19: 77.219.9.159 | P19: 932102781 | Q19: 270391932102781 | R19: DEJU STUDIJA 27dejustudija27@gmail.com270391 | T19: 0
A20: 18 | B20: 20 | C20: TANSSILA DANCE SCHOOL | E20: Iiris | F20: SALMENMAA | G20: iiris.salmenmaa@tanssila.fi | H20: +358 415254116 | I20: HELSINKI | J20: 75 | K20: @tanssila | L20: 200464 | M20: 44968.671 | N20: 45001.736 | O20: 90.139.19.127 | P20: 778329227 | Q20: 200464778329227 | R20: TANSSILA DANCE SCHOOLiiris.salmenmaa@tanssila.fi200464 | T20: 0
A21: 19 | B21: 21 | C21: ONYX DANCE STUUDIO | E21: Julia | F21: RAKOVA | G21: Juliaonyx@mail.ru | H21: +372 53324950 | I21: TALLINN | J21: 69 | L21: 314019 | M21: 44968.814 | N21: 44968.814 | O21: 90.191.32.192 | P21: 376599044 | Q21: 314019376599044 | R21: ONYX DANCE STUUDIOJuliaonyx@mail.ru314019 | T21: 0
A22: 20 | B22: 22 | C22: HOUSE OF BERRIES | E22: Alina | F22: MATVEJEVA | G22: malinawaack@gmail.com | H22: +371 29831175 | I22: RĪGA | J22: 119 | L22: 517885 | M22: 44969.368 | N22: 45330.538 | O22: 77.38.221.235 | P22: 615983790 | Q22: 517885615983790 | R22: HOUSE OF BERRIESmalinawaack@gmail.com517885 | T22: 0
A23: 21 | B23: 23 | C23: DANCE ART STUDIO SUNRISE | E23: Karina | F23: STAVEJEVA | G23: karina.stafejeva@gmail.com | H23: +371 26059098 | I23: RĪGA | J23: 119 | L23: 358978 | M23: 44970.258 | N23: 45677.421 | O23: 77.219.8.56 | P23: 749591488 | Q23: 358978749591488 | R23: DANCE ART STUDIO SUNRISEkarina.stafejeva@gmail.com358978 | T23: 0
A24: 22 | B24: 24 | C24: DANCE GROUP NEPOSEDY / TANTSUANSAMBEL NEPOSEDÕ | E24: Liina | F24: BARANOVA | G24: neposedo@gmail.com | H24: +372 59045153 | I24: TALLINN | J24: 69 | L24: 800094 | M24: 44970.433 | N24: 45355.481 | O24: 46.39.145.170 | P24: 906899026 | Q24: 800094906899026 | R24: DANCE GROUP NEPOSEDY / TANTSUANSAMBEL NEPOSEDÕneposedo@gmail.com800094 | T24: 0
A25: 23 | B25: 25 | C25: DEJU STUDIJA DIAMOND GROUP | E25: Jekaterina | F25: VASI&#315;JEVA | G25: diamondgroup@inbox.lv | I25: RĪGA | J25: 119 | L25: 503690 | M25: 44970.893 | N25: 45758.606 | O25: 78.84.128.94 | P25: 181494207 | Q25: 503690181494207 | R25: DEJU STUDIJA DIAMOND GROUPdiamondgroup@inbox.lv503690 | T25: 0
A26: 24 | B26: 26 | C26: DEJU SKOLA “DZIRNAS” | E26: Līga | F26: KAVACE | G26: ligakavace@gmail.com | H26: +371 25134521 | I26: RĪGA | J26: 119 | L26: 534718 | M26: 44971.247 | N26: 44971.247 | O26: 90.139.19.127 | P26: 201430433 | Q26: 534718201430433 | R26: DEJU SKOLA “DZIRNAS”ligakavace@gmail.com534718 | T26: 0
A27: 25 | B27: 27 | C27: DIAMOND | E27: Viana | F27: BARK&#256;NE | G27: viktorijalicite228@gmail.com | I27: LIVĀNI | J27: 119 | L27: 865196 | M27: 44971.608 | N27: 45777.875 | O27: 77.219.1.30 | P27: 985080328 | Q27: 865196985080328 | R27: DIAMONDviktorijalicite228@gmail.com865196 | T27: 0
A28: 26 | B28: 28 | C28: STUDIJA KRISTĀLS | E28: Kristiāna | F28: VINCJUNA | G28: Dejustudija_kristals@inbox.lv | H28: +371 26290501 | I28: SMILTENE | J28: 119 | L28: 994747 | M28: 44972.405 | N28: 44972.405 | O28: 77.219.12.251 | P28: 882069254 | Q28: 994747882069254 | R28: STUDIJA KRISTĀLSDejustudija_kristals@inbox.lv994747 | T28: 0
A29: 27 | B29: 29 | C29: GOLTSMAN BALLET STUDIO | E29: Maria | F29: GOLTSMAN | G29: goltsmanstudio@gmail.com | H29: +372 5062345 | I29: TALLINN | J29: 69 | L29: 303063 | M29: 44972.398 | N29: 44972.457 | O29: 185.244.103.2 | P29: 434412572 | Q29: 303063434412572 | R29: GOLTSMAN BALLET STUDIOgoltsmanstudio@gmail.com303063 | T29: 0
A30: 28 | B30: 30 | C30: STUUDIO JOY | E30: Marina | F30: JERJOMINA | G30: stuudiojoy@gmail.com | H30: +372 5100838 | I30: VALGA / TALLINN | J30: 69 | L30: 350479 | M30: 44972.472 | N30: 44999.405 | O30: 62.63.152.13 | P30: 482695504 | Q30: 350479482695504 | R30: STUUDIO JOY stuudiojoy@gmail.com350479 | T30: 0
A31: 29 | B31: 31 | C31: DANCE GROUP NEXT | E31: Konstantin | F31: KOLESNIKOV | G31: stapdancer@gmail.com | H31: +371 29533395 | I31: RĪGA | J31: 119 | L31: 676118 | M31: 44972.519 | N31: 45693.493 | O31: 90.139.19.127 | P31: 788141270 | Q31: 676118788141270 | R31: DANCE GROUP NEXTstapdancer@gmail.com676118 | T31: 0
A32: 30 | B32: 32 | C32: PREMIUM DANCE STUDIO | E32: Elīna | F32: ALEKSANDROVA | G32: premiumds@inbox.lv | H32: +371 29550531 | I32: RĪGA | J32: 119 | L32: 700686 | M32: 44972.522 | N32: 45679.469 | O32: 90.139.19.127 | P32: 751730266 | Q32: 700686751730266 | R32: PREMIUM DANCE STUDIOpremiumds@inbox.lv700686 | T32: 0
A33: 31 | B33: 33 | C33: TDB DANCE STUDIO | D33: NATALIA | E33: Tereza | F33: DINULA | G33: dancestudiotdb@gmail.com | H33: +371 26362908 | I33: R&#298;GA | J33: 119 | L33: 130685 | M33: 44973.311 | N33: 45938.811 | O33: 213.175.126.8 | P33: 631427387 | Q33: 130685631427387 | R33: TDB DANCE STUDIOdancestudiotdb@gmail.com130685 | T33: 0
A34: 32 | B34: 34 | C34: FLASH DANCE STUDIO | E34: Marina | F34: UNGURE | G34: a.filistejeva@inbox.lv | H34: +371 25926114 | I34: R&#298;GA | J34: 119 | K34: flash.dancestudio | L34: 316407 | M34: 44973.403 | N34: 45939.778 | O34: 90.139.19.127 | P34: 685303811 | Q34: 316407685303811 | R34: FLASH DANCE STUDIOa.filistejeva@inbox.lv316407 | T34: 0
A35: 33 | B35: 35 | C35: DANCING CRYSTAL | E35: Tatjana | F35: ZAGORSKA-UDAĻCOVA | G35: tatjana0505@inbox.lv | H35: +371 22014412 | I35: PĻAVIŅAS | J35: 119 | L35: 372754 | M35: 44973.853 | N35: 44973.855 | O35: 78.84.231.104 | P35: 475005630 | Q35: 372754475005630 | R35: DANCING CRYSTALtatjana0505@inbox.lv372754 | T35: 0
A36: 34 | B36: 36 | C36: DA KARUSELIS, DS CAROUSELL | E36: Tamara | F36: EIFEROVA | G36: tamara.eiferova@gmail.com | H36: +371 29491491 | I36: SALASPILS | J36: 119 | L36: 121662 | M36: 44974.352 | N36: 45350.382 | O36: 87.110.33.86 | P36: 654349494 | Q36: 121662654349494 | R36: DA KARUSELIS, DS CAROUSELLtamara.eiferova@gmail.com121662 | T36: 0
A37: 35 | B37: 37 | C37: DANCE STUDIO CIPRESE | E37: Patrīcija | F37: DANILEIKO | G37: patricijapetrovska@gmail.com | H37: +371 29921147 | I37: RĪGA | J37: 119 | L37: 609425 | M37: 44977.346 | N37: 45362.531 | O37: 77.38.166.178 | P37: 604190403 | Q37: 609425604190403 | R37: DANCE STUDIO CIPRESEpatricijapetrovska@gmail.com609425 | T37: 0
A38: 36 | B38: 38 | C38: RITMS | E38: Elina | F38: GAITJUKEVICA | G38: ritms@ritms.lv | H38: +371 29592133 | I38: RĪGA | J38: 119 | L38: 786449 | M38: 44977.782 | N38: 45371.464 | O38: 80.89.74.250 | P38: 513992270 | Q38: 786449513992270 | R38: RITMSritms@ritms.lv786449 | T38: 0
A39: 37 | B39: 39 | C39: FREAK DANCE | E39: Sofija anna | F39: ZADOROŽNAJA | G39: freakxxxdance@gmail.com | H39: +371 26682346 | I39: RĪGA | J39: 119 | K39: freak.x.dance | L39: 984448 | M39: 44978.582 | N39: 44978.595 | O39: 81.198.169.234 | P39: 535565465 | Q39: 984448535565465 | R39: FREAK DANCEfreakxxxdance@gmail.com984448 | T39: 0
A40: 38 | B40: 40 | C40: X-GENERATION | E40: Jelena | F40: KOVALENKO | G40: jelena.kovalenko75@gmail.com | H40: +372 5577759 | I40: TALLINN | J40: 69 | L40: 823405 | M40: 44978.624 | N40: 45688.813 | O40: 91.129.103.199 | P40: 476610299 | Q40: 823405476610299 | R40: X-GENERATIONjelena.kovalenko75@gmail.com823405 | T40: 0
...

Sheet acts
A1: _RowNum | B1: act_ID | C1: eventID | D1: eventname | E1: studioID | F1: teamname | G1: actname | H1: act_format | I1: act_type | J1: comp_numbers | K1: act_nomination | L1: act_agegroup | M1: act_division | N1: act_min_age | O1: act_max_age | P1: mixedage | Q1: notes | R1: datecreated | S1: lastupdated | T1: duplicates | U1: filler
A2: 0 | B2: 6 | C2: 7 | D2: Riga | E2: 3 | F2: MADNESS TEAM | G2: ILLUSION | H2: group | K2: stage dance | L2: adult 18+ | R2: 45932.55 | S2: 45932.55 | T2: 3/7/MADNESS TEAM
A3: 1 | B3: 7 | C3: 7 | D3: Riga | E3: 3 | F3: MADNESS TEAM | G3: BUTTERFLY EFFECT | H3: group | K3: stage dance | L3: adult 18+ | R3: 45932.551 | S3: 45932.551 | T3: 3/7/MADNESS TEAM
A4: 2 | B4: 8 | C4: 7 | D4: Riga | E4: 3 | F4: MADNESS TEAM | G4: SYMBIOSIS | H4: group | K4: stage dance | L4: adult 18+ | R4: 45932.552 | S4: 45932.552 | T4: 3/7/MADNESS TEAM
A5: 3 | B5: 9 | C5: 9 | D5: World of Dance Latvia | E5: 3 | F5: MADNESS TEAM | G5: ILLUSION | H5: group | K5: stage dance | L5: over 18s | M5: Team | R5: 45932.553 | S5: 45932.553 | T5: 3/9/MADNESS TEAM
A6: 4 | B6: 10 | C6: 9 | D6: World of Dance Latvia | E6: 3 | F6: MADNESS TEAM | G6: BUTTERFLY EFFECT | H6: group | K6: stage dance | L6: over 18s | M6: Team | R6: 45932.554 | S6: 45932.554 | T6: 3/9/MADNESS TEAM
A7: 5 | B7: 11 | C7: 9 | D7: World of Dance Latvia | E7: 3 | F7: MADNESS TEAM | G7: SYMBIOSIS | H7: group | K7: stage dance | L7: over 18s | M7: Team | R7: 45932.554 | S7: 45932.554 | T7: 3/9/MADNESS TEAM
A8: 6 | B8: 12 | C8: 7 | D8: Riga | E8: 88 | F8: DANCEACT DANCE STUDIO | G8: 1 | H8: group | K8: contemp & modern | L8: 16-18 y | R8: 45939.378 | S8: 45939.378 | T8: 88/7/DANCEACT DANCE STUDIO
A9: 7 | B9: 13 | C9: 7 | D9: Riga | E9: 88 | F9: DANCEACT DANCE STUDIO | G9: 2 | H9: group | K9: stage dance | L9: 16-18 y | R9: 45939.379 | S9: 45939.379 | T9: 88/7/DANCEACT DANCE STUDIO
A10: 8 | B10: 14 | C10: 7 | D10: Riga | E10: 88 | F10: DANCEACT DANCE STUDIO | G10: 3 | H10: group | K10: stage dance | L10: adult 18+ | R10: 45939.379 | S10: 45939.379 | T10: 88/7/DANCEACT DANCE STUDIO
A11: 9 | B11: 15 | C11: 7 | D11: Riga | E11: 88 | F11: DANCEACT DANCE STUDIO | G11: 4 | H11: group | K11: stage dance | L11: 16-18 y | R11: 45939.379 | S11: 45939.379 | T11: 88/7/DANCEACT DANCE STUDIO
A12: 10 | B12: 16 | C12: 7 | D12: Riga | E12: 88 | F12: DANCEACT DANCE STUDIO | G12: 5 | H12: group | K12: folk style dance | L12: 16-18 y | R12: 45939.38 | S12: 45939.38 | T12: 88/7/DANCEACT DANCE STUDIO
A13: 11 | B13: 17 | C13: 7 | D13: Riga | E13: 191 | F13: CRYSTALS | G13: THIS IS US | H13: group | K13: contemp & modern | L13: 10-12 y | R13: 45939.581 | S13: 45939.581 | T13: 191/7/CRYSTALS
A14: 12 | B14: 18 | C14: 7 | D14: Riga | E14: 191 | F14: ROSE PETALS | G14: ORDINARY | H14: group | K14: contemp & modern | L14: 10-12 y | R14: 45939.583 | S14: 45939.583 | T14: 191/7/ROSE PETALS
A15: 13 | B15: 19 | C15: 7 | D15: Riga | E15: 191 | F15: MERMAIDS | G15: BRIGHT STARS | H15: group | K15: contemp & modern | L15: 7-9 y | R15: 45939.584 | S15: 45939.584 | T15: 191/7/MERMAIDS
A16: 14 | B16: 20 | C16: 7 | D16: Riga | E16: 191 | F16: HIP HOP MINIONS | G16: URBAN KIDZ | H16: group | K16: hip hop & urban | L16: 10-12 y | R16: 45939.584 | S16: 45939.584 | T16: 191/7/HIP HOP MINIONS
A17: 15 | B17: 21 | C17: 7 | D17: Riga | E17: 182 | F17: BLENDED CREW | G17: COLLECTIVE PULS | H17: group | K17: contemp & modern | L17: adult 18+ | R17: 45946.503 | S17: 45946.503 | T17: 182/7/BLENDED CREW
A18: 16 | B18: 22 | C18: 9 | D18: World of Dance Latvia | E18: 199 | F18: ALICE SOSNOVSKA | G18: YOU CAN'T OUTRUN A SHADOW | H18: solo | K18: stage dance | L18: over 18s | M18: Styles | R18: 45953.541 | S18: 45953.541 | T18: 199/9/ALICE SOSNOVSKA
A19: 17 | B19: 23 | C19: 9 | D19: World of Dance Latvia | E19: 200 | F19: ANNA DUDARCHYK | G19: - | H19: solo | K19: stage dance | L19: over 18s | M19: 0 | R19: 45956.87 | S19: 45956.87 | T19: 200/9/ANNA DUDARCHYK
A20: 18 | B20: 24 | C20: 7 | D20: Riga | E20: 88 | F20: DANCEACT DANCE STUDIO | G20: 1 | H20: group | K20: stage dance | L20: 13-15 y | R20: 45967.592 | S20: 45967.592 | T20: 88/7/DANCEACT DANCE STUDIO
A21: 19 | B21: 25 | C21: 7 | D21: Riga | E21: 88 | F21: DANCEACT DANCE STUDIO | G21: 7 | H21: group | K21: hip hop & urban | L21: 16-18 y | R21: 45967.602 | S21: 45967.602 | T21: 88/7/DANCEACT DANCE STUDIO
A22: 20 | B22: 26 | C22: 8 | D22: Turkey | E22: 199 | F22: ALICE SOSNOVSKA | G22: STRIKEOUT | H22: solo | K22: hip hop & urban | L22: adult 18+ | R22: 45971.909 | S22: 45971.909 | T22: 199/8/ALICE SOSNOVSKA
A23: 21 | B23: 27 | C23: 8 | D23: Turkey | E23: 193 | F23: GIFFORD DANCE ACADEMY | G23: TEARS OF AN ANGEL | H23: group | K23: contemp & jazz-modern | L23: 13-15 y | R23: 45981.61 | S23: 45981.61 | T23: 193/8/GIFFORD DANCE ACADEMY
A24: 22 | B24: 28 | C24: 7 | D24: Riga | E24: 186 | F24: UNIQSY | G24: UNIVERSE WARRIORS | H24: group | K24: stage dance | L24: 13-15 y | R24: 45982.03 | S24: 45982.03 | T24: 186/7/UNIQSY
A25: 23 | B25: 29 | C25: 8 | D25: Turkey | E25: 193 | F25: GIFFORD DANCE ACADEMY | G25: THE WINNER TAKES IT ALL | H25: group | K25: contemp & jazz-modern | L25: 13-15 y | R25: 45983.47 | S25: 45983.47 | T25: 193/8/GIFFORD DANCE ACADEMY
A26: 24 | B26: 30 | C26: 8 | D26: Turkey | E26: 193 | F26: GIFFORD DANCE ACADEMY | G26: AIN'T NO OTHER MAN | H26: group | K26: contemp & jazz-modern | L26: 13-15 y | R26: 45983.471 | S26: 45983.471 | T26: 193/8/GIFFORD DANCE ACADEMY
A27: 25 | B27: 31 | C27: 8 | D27: Turkey | E27: 193 | F27: GIFFORD DANCE ACADEMY | G27: TAKE IT ALL | H27: group | K27: contemp & jazz-modern | L27: 13-15 y | R27: 45983.472 | S27: 45983.472 | T27: 193/8/GIFFORD DANCE ACADEMY
A28: 26 | B28: 32 | C28: 8 | D28: Turkey | E28: 193 | F28: GIFFORD DANCE ACADEMY | G28: HEAVEN IS A PLACE ON EARTH | H28: solo | K28: contemp & jazz-modern | L28: 10-12 y | R28: 45985.749 | S28: 45985.749 | T28: 193/8/GIFFORD DANCE ACADEMY
A29: 27 | B29: 33 | C29: 8 | D29: Turkey | E29: 193 | F29: GIFFORD DANCE ACADEMY | G29: SWEET CHILD Oâ€™MINE | H29: solo | K29: contemp & jazz-modern | L29: 10-12 y | R29: 45985.75 | S29: 45985.75 | T29: 193/8/GIFFORD DANCE ACADEMY
A30: 28 | B30: 34 | C30: 8 | D30: Turkey | E30: 193 | F30: GIFFORD DANCE ACADEMY | G30: ALWAYS REMEMBER US THIS WAY | H30: duo | K30: contemp & jazz-modern | L30: 10-12 y | R30: 45985.751 | S30: 45985.751 | T30: 193/8/GIFFORD DANCE ACADEMY
A31: 29 | B31: 35 | C31: 8 | D31: Turkey | E31: 193 | F31: GIFFORD DANCE ACADEMY | G31: GOOD TO GO | H31: duo | K31: contemp & jazz-modern | L31: 13-15 y | R31: 45985.752 | S31: 45985.752 | T31: 193/8/GIFFORD DANCE ACADEMY
... A33: 31 | B33: 37 | C33: 8 | D33: Turkey | E33: 203 | F33: LADY ELASTIC | G33: PASSION | H33: solo | K33: contemp & jazz-modern | L33: adult 18+ | R33: 45985.923 | S33: 45985.923 | T33: 203/8/LADY ELASTIC
A34: 32 | B34: 38 | C34: 9 | D34: World of Dance Latvia | E34: 205 | F34: SUN+ MINIT | G34: GET UP! | H34: group | K34: hip hop & urban | L34: under 18s | M34: Junior | R34: 45992.552 | S34: 45992.552 | T34: 205/9/SUN+ MINIT

Sheet dancers
A1: _RowNum | B1: dancer_ID | C1: studioID | D1: dancer | E1: dateofbirth | F1: dd_dob | G1: mm_dob | H1: year_dob | I1: datecreated | J1: lastupdated | K1: duplicates | L1: filler
A2: 0 | B2: 1 | C2: 3 | D2: Marija Smiolenkova | E2: 34931 | F2: 20 | G2: 8 | H2: 1995 | I2: 45938.593 | J2: 45938.593 | K2: Marija Smiolenkova20/08/1995
A3: 1 | B3: 2 | C3: 3 | D3: ⁠Nataļja Dorošenko | E3: 35321 | F3: 13 | G3: 9 | H3: 1996 | I3: 45938.593 | J3: 45938.593 | K3: ⁠Nataļja Dorošenko13/09/1996
A4: 2 | B4: 3 | C4: 3 | D4: ⁠Viktorija Urbāne | E4: 36384 | F4: 12 | G4: 8 | H4: 1999 | I4: 45938.593 | J4: 45938.593 | K4: ⁠Viktorija Urbāne12/08/1999
A5: 3 | B5: 4 | C5: 3 | D5: Ksenija Sidorova | E5: 34541 | F5: 26 | G5: 7 | H5: 1994 | I5: 45938.593 | J5: 45938.593 | K5: Ksenija Sidorova26/07/1994
A6: 4 | B6: 5 | C6: 3 | D6: ⁠Darja Šiškina | E6: 35779 | F6: 15 | G6: 12 | H6: 1997 | I6: 45938.593 | J6: 45938.593 | K6: ⁠Darja Šiškina15/12/1997
A7: 5 | B7: 6 | C7: 3 | D7: Nikola Andrejeva | E7: 36071 | F7: 3 | G7: 10 | H7: 1998 | I7: 45938.593 | J7: 45938.593 | K7: Nikola Andrejeva03/10/1998
A8: 6 | B8: 7 | C8: 3 | D8: ⁠Alīna Demidova | E8: 32309 | F8: 15 | G8: 6 | H8: 1988 | I8: 45938.593 | J8: 45938.593 | K8: ⁠Alīna Demidova15/06/1988
A9: 7 | B9: 8 | C9: 3 | D9: ⁠Alina Černova | E9: 39643 | F9: 14 | G9: 7 | H9: 2008 | I9: 45938.593 | J9: 45938.593 | K9: ⁠Alina Černova14/07/2008
A10: 8 | B10: 9 | C10: 3 | D10: Jūlija Šveda | E10: 37608 | F10: 18 | G10: 12 | H10: 2002 | I10: 45938.593 | J10: 45938.593 | K10: Jūlija Šveda18/12/2002
A11: 9 | B11: 10 | C11: 3 | D11: ⁠Silvija Zaporožanu | E11: 33622 | F11: 19 | G11: 1 | H11: 1992 | I11: 45938.593 | J11: 45938.593 | K11: ⁠Silvija Zaporožanu19/01/1992
A12: 10 | B12: 11 | C12: 3 | D12: ⁠Ksenija Ulitova | E12: 38546 | F12: 13 | G12: 7 | H12: 2005 | I12: 45938.593 | J12: 45938.593 | K12: ⁠Ksenija Ulitova13/07/2005
A13: 11 | B13: 12 | C13: 3 | D13: Taisija Savina | E13: 38815 | F13: 8 | G13: 4 | H13: 2006 | I13: 45938.593 | J13: 45938.593 | K13: Taisija Savina08/04/2006
... A17: 15 | B17: 16 | C17: 3 | D17: ⁠Anna Aleksandra Romašenoka | E17: 37453 | F17: 16 | G17: 7 | H17: 2002 | I17: 45938.593 | J17: 45938.593 | K17: ⁠Anna Aleksandra Romašenoka16/07/2002

Sheet reserved_places
A1: _RowNum | B1: reserveID | C1: studioID | D1: event1 | E1: riga_acts | F1: riga_dancers | G1: riga_changed | H1: riga_datepaid | I1: riga_money | J1: event2 | K1: belek_acts | L1: belek_dancers | M1: belek_changed | N1: belek_datepaid | O1: belek_money | P1: event3 | Q1: wod_acts | R1: wod_dancers | S1: wod_changed | T1: wod_datepaid | U1: wod_money | V1: lastupdated | W1: eof | X1: block1
A2: 0 | B2: 1 | C2: 2 | D2: 7 | E2: 8 | F2: 79 | G2: 1 | H2: 367 | I2: 0 | J2: 8 | K2: 0 | L2: 0 | M2: 0 | N2: 367 | O2: 0 | P2: 9 | Q2: 2 | R2: 14 | S2: 1 | T2: 367 | U2: 0 | V2: 45932.941 | X2: 0 | Y2: =IFERROR(VLOOKUP(reserved_places[[#This Row],[studioID]],studios!$B:$C,2,FALSE),"") -> ARISTO DANCE
A3: 1 | B3: 2 | C3: 3 | D3: 7 | E3: 2 | F3: 16 | G3: 1 | H3: 367 | I3: 0 | J3: 8 | K3: 0 | L3: 0 | M3: 0 | N3: 367 | O3: 0 | P3: 9 | Q3: 3 | R3: 16 | S3: 1 | T3: 367 | U3: 0 | V3: 45954.581 | X3: 0 | Y3: =IFERROR(VLOOKUP(reserved_places[[#This Row],[studioID]],studios!$B:$C,2,FALSE),"") -> BAZA DANCE COMPANY
A4: 2 | B4: 3 | C4: 4 | D4: 7 | E4: 0 | F4: 0 | G4: 0 | H4: 367 | I4: 0 | J4: 8 | K4: 0 | L4: 0 | M4: 0 | N4: 367 | O4: 0 | P4: 9 | Q4: 0 | R4: 0 | S4: 0 | T4: 367 | U4: 0 | V4: 45929 | X4: 0 | Y4: =IFERROR(VLOOKUP(reserved_places[[#This Row],[studioID]],studios!$B:$C,2,FALSE),"") -> ZFORCE
A5: 3 | B5: 4 | C5: 5 | D5: 7 | E5: 0 | F5: 0 | G5: 0 | H5: 367 | I5: 0 | J5: 8 | K5: 0 | L5: 0 | M5: 0 | N5: 367 | O5: 0 | P5: 9 | Q5: 0 | R5: 0 | S5: 0 | T5: 367 | U5: 0 | V5: 45929 | X5: 0 | Y5: =IFERROR(VLOOKUP(reserved_places[[#This Row],[studioID]],studios!$B:$C,2,FALSE),"") -> MUSTAMÄE HUVIKOOL ESTRAADITANTSUKOOL PEPPY DANCE
A6: 4 | B6: 5 | C6: 6 | D6: 7 | E6: 0 | F6: 0 | G6: 0 | H6: 367 | I6: 0 | J6: 8 | K6: 0 | L6: 0 | M6: 0 | N6: 367 | O6: 0 | P6: 9 | Q6: 0 | R6: 0 | S6: 0 | T6: 367 | U6: 0 | V6: 45929 | X6: 0 | Y6: =IFERROR(VLOOKUP(reserved_places[[#This Row],[studioID]],studios!$B:$C,2,FALSE),"") -> TANSSIVA PORVOO
A7: 5 | B7: 6 | C7: 7 | D7: 7 | E7: 0 | F7: 0 | G7: 0 | H7: 367 | I7: 0 | J7: 8 | K7: 0 | L7: 0 | M7: 0 | N7: 367 | O7: 0 | P7: 9 | Q7: 0 | R7: 0 | S7: 0 | T7: 367 | U7: 0 | V7: 45929 | X7: 0 | Y7: =IFERROR(VLOOKUP(reserved_places[[#This Row],[studioID]],studios!$B:$C,2,FALSE),"") -> 1ST CUT DANCE BASE
A8: 6 | B8: 7 | C8: 8 | D8: 7 | E8: 0 | F8: 0 | G8: 0 | H8: 367 | I8: 0 | J8: 8 | K8: 0 | L8: 0 | M8: 0 | N8: 367 | O8: 0 | P8: 9 | Q8: 0 | R8: 0 | S8: 0 | T8: 367 | U8: 0 | V8: 45929 | X8: 0 | Y8: =IFERROR(VLOOKUP(reserved_places[[#This Row],[studioID]],studios!$B:$C,2,FALSE),"") -> CHOREOGRAPHY STUDIO INKARELIS
A9: 7 | B9: 8 | C9: 9 | D9: 7 | E9: 10 | F9: 150 | G9: 1 | H9: 367 | I9: 0 | J9: 8 | K9: 0 | L9: 0 | M9: 0 | N9: 367 | O9: 0 | P9: 9 | Q9: 0 | R9: 0 | S9: 0 | T9: 367 | U9: 0 | V9: 45939.446 | X9: 0 | Y9: =IFERROR(VLOOKUP(reserved_places[[#This Row],[studioID]],studios!$B:$C,2,FALSE),"") -> DE ARTE
A10: 8 | B10: 9 | C10: 10 | D10: 7 | E10: 5 | F10: 65 | G10: 1 | H10: 367 | I10: 0 | J10: 8 | K10: 0 | L10: 0 | M10: 0 | N10: 367 | O10: 0 | P10: 9 | Q10: 0 | R10: 0 | S10: 0 | T10: 367 | U10: 0 | V10: 45938.525 | X10: 0 | Y10: =IFERROR(VLOOKUP(reserved_places[[#This Row],[studioID]],studios!$B:$C,2,FALSE),"") -> DREAM DANCE STUDIO
A11: 9 | B11: 10 | C11: 11 | D11: 7 | E11: 0 | F11: 0 | G11: 0 | H11: 367 | I11: 0 | J11: 8 | K11: 0 | L11: 0 | M11: 0 | N11: 367 | O11: 0 | P11: 9 | Q11: 0 | R11: 0 | S11: 0 | T11: 367 | U11: 0 | V11: 45929 | X11: 0 | Y11: =IFERROR(VLOOKUP(reserved_places[[#This Row],[studioID]],studios!$B:$C,2,FALSE),"") -> DANCE STUDIO STARMIX
A12: 10 | B12: 11 | C12: 12 | D12: 7 | E12: 0 | F12: 0 | G12: 0 | H12: 367 | I12: 0 | J12: 8 | K12: 0 | L12: 0 | M12: 0 | N12: 367 | O12: 0 | P12: 9 | Q12: 0 | R12: 0 | S12: 0 | T12: 367 | U12: 0 | V12: 45929 | X12: 0 | Y12: =IFERROR(VLOOKUP(reserved_places[[#This Row],[studioID]],studios!$B:$C,2,FALSE),"") -> VOU DANCE GROUP
A13: 11 | B13: 12 | C13: 13 | D13: 7 | E13: 3 | F13: 16 | G13: 1 | H13: 367 | I13: 0 | J13: 8 | K13: 0 | L13: 0 | M13: 0 | N13: 367 | O13: 0 | P13: 9 | Q13: 0 | R13: 0 | S13: 0 | T13: 367 | U13: 0 | V13: 45938.545 | X13: 0 | Y13: =IFERROR(VLOOKUP(reserved_places[[#This Row],[studioID]],studios!$B:$C,2,FALSE),"") -> MS DANCE GROUP
... A233: 231 | B233: 236 | C233: 240 | D233: 7 | E233: 0 | F233: 0 | G233: 0 | H233: 367 | I233: 0 | J233: 8 | K233: 0 | L233: 0 | M233: 0 | N233: 367 | O233: 0 | P233: 9 | Q233: 0 | R233: 0 | S233: 0 | T233: 367 | U233: 0 | V233: 45929 | X233: 0 | Y233: =IFERROR(VLOOKUP(reserved_places[[#This Row],[studioID]],studios!$B:$C,2,FALSE),"")
Y234: =IFERROR(VLOOKUP(reserved_places[[#This Row],[studioID]],studios!$B:$C,2,FALSE),"")

Sheet countries
A1: _RowNum | B1: country_ID | C1: name | D1: iso3 | E1: iso2 | F1: numeric_code | G1: phonecode | H1: capital | I1: currency | J1: currency_name | K1: currency_symbol | L1: tld | M1: native | N1: region | O1: region_id | P1: subregion | Q1: subregion_id | R1: nationality | S1: emoji | T1: emojiU | U1: flag | V1: filler
A2: 0 | B2: 1 | C2: Afghanistan | D2: AFG | E2: AF | F2: 4 | G2: 93 | H2: Kabul | I2: AFN | J2: Afghan afghani | K2: ؋ | L2: .af | M2: افغانستان | N2: Asia | O2: 3 | P2: Southern Asia | Q2: 14 | R2: Afghan | S2: 🇦🇫 | T2: U+1F1E6 U+1F1EB
A3: 1 | B3: 2 | C3: Aland Islands | D3: ALA | E3: AX | F3: 248 | G3: 358 | H3: Mariehamn | I3: EUR | J3: Euro | K3: € | L3: .ax | M3: Åland | N3: Europe | O3: 4 | P3: Northern Europe | Q3: 18 | R3: Aland Island | S3: 🇦🇽 | T3: U+1F1E6 U+1F1FD
A4: 2 | B4: 3 | C4: Albania | D4: ALB | E4: AL | F4: 8 | G4: 355 | H4: Tirana | I4: ALL | J4: Albanian lek | K4: Lek | L4: .al | M4: Shqipëria | N4: Europe | O4: 4 | P4: Southern Europe | Q4: 16 | R4: Albanian | S4: 🇦🇱 | T4: U+1F1E6 U+1F1F1
A5: 3 | B5: 4 | C5: Algeria | D5: DZA | E5: DZ | F5: 12 | G5: 213 | H5: Algiers | I5: DZD | J5: Algerian dinar | K5: دج | L5: .dz | M5: الجزائر | N5: Africa | O5: 1 | P5: Northern Africa | Q5: 1 | R5: Algerian | S5: 🇩🇿 | T5: U+1F1E9 U+1F1FF
A6: 4 | B6: 5 | C6: American Samoa | D6: ASM | E6: AS | F6: 16 | G6: 1 | H6: Pago Pago | I6: USD | J6: United States dollar | K6: $ | L6: .as | M6: American Samoa | N6: Oceania | O6: 5 | P6: Polynesia | Q6: 22 | R6: American Samoan | S6: 🇦🇸 | T6: U+1F1E6 U+1F1F8
A7: 5 | B7: 6 | C7: Andorra | D7: AND | E7: AD | F7: 20 | G7: 376 | H7: Andorra la Vella | I7: EUR | J7: Euro | K7: € | L7: .ad | M7: Andorra | N7: Europe | O7: 4 | P7: Southern Europe | Q7: 16 | R7: Andorran | S7: 🇦🇩 | T7: U+1F1E6 U+1F1E9
A8: 6 | B8: 7 | C8: Angola | D8: AGO | E8: AO | F8: 24 | G8: 244 | H8: Luanda | I8: AOA | J8: Angolan kwanza | K8: Kz | L8: .ao | M8: Angola | N8: Africa | O8: 1 | P8: Middle Africa | Q8: 2 | R8: Angolan | S8: 🇦🇴 | T8: U+1F1E6 U+1F1F4
A9: 7 | B9: 8 | C9: Anguilla | D9: AIA | E9: AI | F9: 660 | G9: 1 | H9: The Valley | I9: XCD | J9: Eastern Caribbean dollar | K9: $ | L9: .ai | M9: Anguilla | N9: Americas | O9: 2 | P9: Caribbean | Q9: 7 | R9: Anguillan | S9: 🇦🇮 | T9: U+1F1E6 U+1F1EE
A10: 8 | B10: 9 | C10: Antarctica | D10: ATA | E10: AQ | F10: 10 | G10: 672 | I10: AAD | J10: Antarctican dollar | K10: $ | L10: .aq | M10: Antarctica | N10: Polar | O10: 6 | R10: Antarctic | S10: 🇦🇶 | T10: U+1F1E6 U+1F1F6
A11: 9 | B11: 10 | C11: Antigua and Barbuda | D11: ATG | E11: AG | F11: 28 | G11: 1 | H11: St. John's | I11: XCD | J11: Eastern Caribbean dollar | K11: $ | L11: .ag | M11: Antigua and Barbuda | N11: Americas | O11: 2 | P11: Caribbean | Q11: 7 | R11: Antiguan or Barbudan | S11: 🇦🇬 | T11: U+1F1E6 U+1F1EC
A12: 10 | B12: 11 | C12: Argentina | D12: ARG | E12: AR | F12: 32 | G12: 54 | H12: Buenos Aires | I12: ARS | J12: Argentine peso | K12: $ | L12: .ar | M12: Argentina | N12: Americas | O12: 2 | P12: South America | Q12: 8 | R12: Argentine | S12: 🇦🇷 | T12: U+1F1E6 U+1F1F7
A13: 11 | B13: 12 | C13: Armenia | D13: ARM | E13: AM | F13: 51 | G13: 374 | H13: Yerevan | I13: AMD | J13: Armenian dram | K13: ֏ | L13: .am | M13: Հայաստան | N13: Asia | O13: 3 | P13: Western Asia | Q13: 11 | R13: Armenian | S13: 🇦🇲 | T13: U+1F1E6 U+1F1F2
A14: 12 | B14: 13 | C14: Aruba | D14: ABW | E14: AW | F14: 533 | G14: 297 | H14: Oranjestad | I14: AWG | J14: Aruban florin | K14: ƒ | L14: .aw | M14: Aruba | N14: Americas | O14: 2 | P14: Caribbean | Q14: 7 | R14: Aruban | S14: 🇦🇼 | T14: U+1F1E6 U+1F1FC
A15: 13 | B15: 14 | C15: Australia | D15: AUS | E15: AU | F15: 36 | G15: 61 | H15: Canberra | I15: AUD | J15: Australian dollar | K15: $ | L15: .au | M15: Australia | N15: Oceania | O15: 5 | P15: Australia and New Zealand | Q15: 19 | R15: Australian | S15: 🇦🇺 | T15: U+1F1E6 U+1F1FA
A16: 14 | B16: 15 | C16: Austria | D16: AUT | E16: AT | F16: 40 | G16: 43 | H16: Vienna | I16: EUR | J16: Euro | K16: € | L16: .at | M16: Österreich | N16: Europe | O16: 4 | P16: Western Europe | Q16: 17 | R16: Austrian | S16: 🇦🇹 | T16: U+1F1E6 U+1F1F9
A17: 15 | B17: 16 | C17: Azerbaijan | D17: AZE | E17: AZ | F17: 31 | G17: 994 | H17: Baku | I17: AZN | J17: Azerbaijani manat | K17: m | L17: .az | M17: Azərbaycan | N17: Asia | O17: 3 | P17: Western Asia | Q17: 11 | R17: Azerbaijani, Azeri | S17: 🇦🇿 | T17: U+1F1E6 U+1F1FF
A18: 16 | B18: 17 | C18: Bahrain | D18: BHR | E18: BH | F18: 48 | G18: 973 | H18: Manama | I18: BHD | J18: Bahraini dinar | K18: .د.ب | L18: .bh | M18: ‏البحرين | N18: Asia | O18: 3 | P18: Western Asia | Q18: 11 | R18: Bahraini | S18: 🇧🇭 | T18: U+1F1E7 U+1F1ED
A19: 17 | B19: 18 | C19: Bangladesh | D19: BGD | E19: BD | F19: 50 | G19: 880 | H19: Dhaka | I19: BDT | J19: Bangladeshi taka | K19: ৳ | L19: .bd | M19: Bangladesh | N19: Asia | O19: 3 | P19: Southern Asia | Q19: 14 | R19: Bangladeshi | S19: 🇧🇩 | T19: U+1F1E7 U+1F1E9
A20: 18 | B20: 19 | C20: Barbados | D20: BRB | E20: BB | F20: 52 | G20: 1 | H20: Bridgetown | I20: BBD | J20: Barbadian dollar | K20: Bds$ | L20: .bb | M20: Barbados | N20: Americas | O20: 2 | P20: Caribbean | Q20: 7 | R20: Barbadian | S20: 🇧🇧 | T20: U+1F1E7 U+1F1E7
A21: 19 | B21: 20 | C21: Belarus | D21: BLR | E21: BY | F21: 112 | G21: 375 | H21: Minsk | I21: BYN | J21: Belarusian ruble | K21: Br | L21: .by | M21: Белару́сь | N21: Europe | O21: 4 | P21: Eastern Europe | Q21: 15 | R21: Belarusian | S21: 🇧🇾 | T21: U+1F1E7 U+1F1FE
A22: 20 | B22: 21 | C22: Belgium | D22: BEL | E22: BE | F22: 56 | G22: 32 | H22: Brussels | I22: EUR | J22: Euro | K22: € | L22: .be | M22: België | N22: Europe | O22: 4 | P22: Western Europe | Q22: 17 | R22: Belgian | S22: 🇧🇪 | T22: U+1F1E7 U+1F1EA
... A30: 28 | B30: 29 | C30: Botswana | D30: BWA | E30: BW | F30: 72 | G30: 267 | H30: Gaborone | I30: BWP | J30: Botswana pula | K30: P | L30: .bw | M30: Botswana | N30: Africa | O30: 1 | P30: Southern Africa | Q30: 5 | R30: Motswana, Botswanan | S30: 🇧🇼 | T30: U+1F1E7 U+1F1FC
A31: 29 | B31: 30 | C31: Bouvet Island | D31: BVT | E31: BV | F31: 74 | G31: 55 | I31: NOK | J31: Norwegian krone | K31: ko | L31: .bv | M31: Bouvetøya | R31: Bouvet Island | S31: 🇧🇻 | T31: U+1F1E7 U+1F1FB
A32: 30 | B32: 31 | C32: Brazil | D32: BRA | E32: BR | F32: 76 | G32: 55 | H32: Brasilia | I32: BRL | J32: Brazilian real | K32: R$ | L32: .br | M32: Brasil | N32: Americas | O32: 2 | P32: South America | Q32: 8 | R32: Brazilian | S32: 🇧🇷 | T32: U+1F1E7 U+1F1F7
A33: 31 | B33: 32 | C33: British Indian Ocean Territory | D33: IOT | E33: IO | F33: 86 | G33: 246 | H33: Diego Garcia | I33: USD | J33: United States dollar | K33: $ | L33: .io | M33: British Indian Ocean Territory | N33: Africa | O33: 1 | P33: Eastern Africa | Q33: 4 | R33: BIOT | S33: 🇮🇴 | T33: U+1F1EE U+1F1F4
A34: 32 | B34: 33 | C34: Brunei | D34: BRN | E34: BN | F34: 96 | G34: 673 | H34: Bandar Seri Begawan | I34: BND | J34: Brunei dollar | K34: B$ | L34: .bn | M34: Negara Brunei Darussalam | N34: Asia | O34: 3 | P34: South-Eastern Asia | Q34: 13 | R34: Bruneian | S34: 🇧🇳 | T34: U+1F1E7 U+1F1F3
A35: 33 | B35: 34 | C35: Bulgaria | D35: BGR | E35: BG | F35: 100 | G35: 359 | H35: Sofia | I35: BGN | J35: Bulgarian lev | K35: Лв. | L35: .bg | M35: България | N35: Europe | O35: 4 | P35: Eastern Europe | Q35: 15 | R35: Bulgarian | S35: 🇧🇬 | T35: U+1F1E7 U+1F1EC
A36: 34 | B36: 35 | C36: Burkina Faso | D36: BFA | E36: BF | F36: 854 | G36: 226 | H36: Ouagadougou | I36: XOF | J36: West African CFA franc | K36: CFA | L36: .bf | M36: Burkina Faso | N36: Africa | O36: 1 | P36: Western Africa | Q36: 3 | R36: Burkinabe | S36: 🇧🇫 | T36: U+1F1E7 U+1F1EB
A37: 35 | B37: 36 | C37: Burundi | D37: BDI | E37: BI | F37: 108 | G37: 257 | H37: Bujumbura | I37: BIF | J37: Burundian franc | K37: FBu | L37: .bi | M37: Burundi | N37: Africa | O37: 1 | P37: Eastern Africa | Q37: 4 | R37: Burundian | S37: 🇧🇮 | T37: U+1F1E7 U+1F1EE
A38: 36 | B38: 37 | C38: Cambodia | D38: KHM | E38: KH | F38: 116 | G38: 855 | H38: Phnom Penh | I38: KHR | J38: Cambodian riel | K38: KHR | L38: .kh | M38: Kâmpŭchéa | N38: Asia | O38: 3 | P38: South-Eastern Asia | Q38: 13 | R38: Cambodian | S38: 🇰🇭 | T38: U+1F1F0 U+1F1ED
A39: 37 | B39: 38 | C39: Cameroon | D39: CMR | E39: CM | F39: 120 | G39: 237 | H39: Yaounde | I39: XAF | J39: Central African CFA franc | K39: FCFA | L39: .cm | M39: Cameroon | N39: Africa | O39: 1 | P39: Middle Africa | Q39: 2 | R39: Cameroonian | S39: 🇨🇲 | T39: U+1F1E8 U+1F1F2
A40: 38 | B40: 39 | C40: Canada | D40: CAN | E40: CA | F40: 124 | G40: 1 | H40: Ottawa | I40: CAD | J40: Canadian dollar | K40: $ | L40: .ca | M40: Canada | N40: Americas | O40: 2 | P40: Northern America | Q40: 6 | R40: Canadian | S40: 🇨🇦 | T40: U+1F1E8 U+1F1E6
A41: 39 | B41: 40 | C41: Cape Verde | D41: CPV | E41: CV | F41: 132 | G41: 238 | H41: Praia | I41: CVE | J41: Cape Verdean escudo | K41: $ | L41: .cv | M41: Cabo Verde | N41: Africa | O41: 1 | P41: Western Africa | Q41: 3 | R41: Verdean | S41: 🇨🇻 | T41: U+1F1E8 U+1F1FB
A42: 40 | B42: 41 | C42: Cayman Islands | D42: CYM | E42: KY | F42: 136 | G42: 1 | H42: George Town | I42: KYD | J42: Cayman Islands dollar | K42: $ | L42: .ky | M42: Cayman Islands | N42: Americas | O42: 2 | P42: Caribbean | Q42: 7 | R42: Caymanian | S42: 🇰🇾 | T42: U+1F1F0 U+1F1FE
A43: 41 | B43: 42 | C43: Central African Republic | D43: CAF | E43: CF | F43: 140 | G43: 236 | H43: Bangui | I43: XAF | J43: Central African CFA franc | K43: FCFA | L43: .cf | M43: Ködörösêse tî Bêafrîka | N43: Africa | O43: 1 | P43: Middle Africa | Q43: 2 | R43: Central African | S43: 🇨🇫 | T43: U+1F1E8 U+1F1EB
... A53: 51 | B53: 52 | C53: Costa Rica | D53: CRI | E53: CR | F53: 188 | G53: 506 | H53: San Jose | I53: CRC | J53: Costa Rican colón | K53: ₡ | L53: .cr | M53: Costa Rica | N53: Americas | O53: 2 | P53: Central America | Q53: 9 | R53: Costa Rican | S53: 🇨🇷 | T53: U+1F1E8 U+1F1F7
A54: 52 | B54: 53 | C54: Cote D'Ivoire (Ivory Coast) | D54: CIV | E54: CI | F54: 384 | G54: 225 | H54: Yamoussoukro | I54: XOF | J54: West African CFA franc | K54: CFA | L54: .ci | N54: Africa | O54: 1 | P54: Western Africa | Q54: 3 | R54: Ivorian | S54: 🇨🇮 | T54: U+1F1E8 U+1F1EE
A55: 53 | B55: 54 | C55: Croatia | D55: HRV | E55: HR | F55: 191 | G55: 385 | H55: Zagreb | I55: EUR | J55: Euro | K55: € | L55: .hr | M55: Hrvatska | N55: Europe | O55: 4 | P55: Southern Europe | Q55: 16 | R55: Croatian | S55: 🇭🇷 | T55: U+1F1ED U+1F1F7
A56: 54 | B56: 55 | C56: Cuba | D56: CUB | E56: CU | F56: 192 | G56: 53 | H56: Havana | I56: CUP | J56: Cuban peso | K56: $ | L56: .cu | M56: Cuba | N56: Americas | O56: 2 | P56: Caribbean | Q56: 7 | R56: Cuban | S56: 🇨🇺 | T56: U+1F1E8 U+1F1FA
...

Sheet SaveToDB_Data
A1: ID
A2: Start Fields of object [s4d_2025.dbo.studios] on server [2.59.119.221]
D3: studio_ID | E3: 1 | G3: FALSE | H3: TRUE | I3: FALSE | J3: int | L3: 10 | M3: 0 | N3: TRUE | O3: studio_ID | V3: FALSE | W3: TRUE
D4: studioname | E4: 2 | G4: FALSE | H4: FALSE | I4: FALSE | J4: nvarchar | K4: 50 | N4: FALSE | O4: studioname | V4: FALSE | W4: TRUE
D5: contact | E5: 3 | G5: TRUE | H5: FALSE | I5: FALSE | J5: nvarchar | K5: 50 | N5: FALSE | O5: contact | V5: FALSE | W5: TRUE
D6: fname | E6: 4 | G6: TRUE | H6: FALSE | I6: FALSE | J6: nvarchar | K6: 30 | N6: FALSE | O6: fname | V6: FALSE | W6: TRUE
D7: surname | E7: 5 | G7: TRUE | H7: FALSE | I7: FALSE | J7: nvarchar | K7: 30 | N7: FALSE | O7: surname | V7: FALSE | W7: TRUE
D8: email | E8: 6 | G8: TRUE | H8: FALSE | I8: FALSE | J8: nvarchar | K8: 80 | N8: FALSE | O8: email | V8: FALSE | W8: TRUE
D9: mobile | E9: 7 | G9: TRUE | H9: FALSE | I9: FALSE | J9: nvarchar | K9: 20 | N9: FALSE | O9: mobile | V9: FALSE | W9: TRUE
D10: city | E10: 8 | G10: TRUE | H10: FALSE | I10: FALSE | J10: nvarchar | K10: 50 | N10: FALSE | O10: city | V10: FALSE | W10: TRUE
D11: countryID | E11: 9 | G11: TRUE | H11: FALSE | I11: FALSE | J11: int | L11: 10 | M11: 0 | N11: FALSE | O11: countryID | V11: FALSE | W11: TRUE
D12: instagram | E12: 10 | G12: TRUE | H12: FALSE | I12: FALSE | J12: nvarchar | K12: 50 | N12: FALSE | O12: instagram | V12: FALSE | W12: TRUE
D13: pincode | E13: 11 | G13: TRUE | H13: FALSE | I13: FALSE | J13: int | L13: 10 | M13: 0 | N13: FALSE | O13: pincode | V13: FALSE | W13: TRUE
D14: datecreated | E14: 12 | G14: TRUE | H14: FALSE | I14: FALSE | J14: datetime | L14: 3 | N14: FALSE | O14: datecreated | V14: FALSE | W14: TRUE
D15: lastupdated | E15: 13 | G15: TRUE | H15: FALSE | I15: FALSE | J15: datetime | L15: 3 | N15: FALSE | O15: lastupdated | V15: FALSE | W15: TRUE
D16: ipaddress | E16: 14 | G16: TRUE | H16: FALSE | I16: FALSE | J16: nvarchar | K16: 16 | N16: FALSE | O16: ipaddress | V16: FALSE | W16: TRUE
D17: sessionID | E17: 15 | G17: TRUE | H17: FALSE | I17: FALSE | J17: bigint | L17: 19 | M17: 0 | N17: FALSE | O17: sessionID | V17: FALSE | W17: TRUE
D18: secureno | E18: 16 | G18: TRUE | H18: FALSE | I18: FALSE | J18: bigint | L18: 19 | M18: 0 | N18: FALSE | O18: secureno | V18: FALSE | W18: TRUE
D19: duplicates | E19: 17 | G19: TRUE | H19: FALSE | I19: FALSE | J19: nvarchar | K19: 140 | N19: FALSE | O19: duplicates | V19: FALSE | W19: TRUE
D20: bulk_link | E20: 18 | G20: TRUE | H20: FALSE | I20: FALSE | J20: varchar | K20: -1 | N20: FALSE | O20: bulk_link | V20: FALSE | W20: TRUE
D21: bulk_uploaded | E21: 19 | F21: ((0)) | G21: TRUE | H21: FALSE | I21: FALSE | J21: bit | N21: FALSE | O21: bulk_uploaded | V21: FALSE | W21: TRUE
D22: filler | E22: 20 | G22: TRUE | H22: FALSE | I22: FALSE | J22: nchar | K22: 1 | N22: FALSE | O22: filler | V22: FALSE | W22: TRUE
A23: End Fields of object [s4d_2025.dbo.studios] on server [2.59.119.221]
A24: Start Last Connect to DB values
A25: 2.59.119.221 | B25: FALSE | C25: saf_s4d | D25: s4d_2025 | E25: (Default) | F25: Provider=SQLOLEDB
A26: End Last Connect to DB values
A27: Start Objects of query object [s4d_2025.(Default)] on server [2.59.119.221]
C28: dbo | D28: acts | E28: TABLE | I28: dbo.acts
C29: dbo | D29: countries | E29: TABLE | I29: dbo.countries
C30: dbo | D30: dancers | E30: TABLE | I30: dbo.dancers
C31: dbo | D31: reserved_places | E31: TABLE | I31: dbo.reserved_places
C32: dbo | D32: studios | E32: TABLE | I32: dbo.studios
A33: End Objects of query object [s4d_2025.(Default)] on server [2.59.119.221]
A34: Start ListObjects
A35: studios | B35: (Default) | C35: FALSE | D35: dbo.studios | E35: TABLE | W35: dbo.studios | Z35: FALSE | AA35: dbo.studios | AH35: dd/MM/yyyy | AI35: HH:mm:ss | AJ35: _none_ | AK35: FALSE | AL35: FALSE
A36: acts | B36: (Default) | C36: FALSE | D36: dbo.acts | E36: TABLE | W36: dbo.acts | Z36: FALSE | AA36: dbo.acts | AH36: dd/MM/yyyy | AI36: HH:mm:ss | AJ36: _none_ | AK36: FALSE | AL36: FALSE
A37: dancers | B37: (Default) | C37: FALSE | D37: dbo.dancers | E37: TABLE | W37: dbo.dancers | Z37: FALSE | AA37: dbo.dancers | AE37: en-GB | AF37: . | AG37: , | AH37: dd/MM/yyyy | AI37: HH:mm:ss | AJ37: _none_ | AK37: FALSE | AL37: FALSE
A38: reserved_places | B38: (Default) | C38: FALSE | D38: dbo.reserved_places | E38: TABLE | W38: dbo.reserved_places | Z38: FALSE | AA38: dbo.reserved_places | AE38: en-GB | AF38: . | AG38: , | AH38: dd/MM/yyyy | AI38: HH:mm:ss | AJ38: _none_ | AK38: FALSE | AL38: FALSE
A39: countries | B39: (Default) | C39: FALSE | D39: dbo.countries | E39: TABLE | W39: dbo.countries | Z39: FALSE | AA39: dbo.countries | AE39: en-GB | AF39: . | AG39: , | AH39: dd/MM/yyyy | AI39: HH:mm:ss | AJ39: _none_ | AK39: FALSE | AL39: FALSE
A40: End ListObjects
...

Sheet SaveToDB_LoadedID
A1: ID
A2: Start IDs of object [dbo.countries] on sheet [countries]
A3: _RowNum | B3: country_ID | C3: name | D3: iso3 | E3: iso2 | F3: numeric_code | G3: phonecode | H3: capital | I3: currency | J3: currency_name | K3: currency_symbol | L3: tld | M3: native | N3: region | O3: region_id | P3: subregion | Q3: subregion_id | R3: nationality | S3: emoji | T3: emojiU | U3: flag | V3: filler
A4: 0 | B4: 1 | C4: Afghanistan | D4: AFG | E4: AF | F4: 4 | G4: 93 | H4: Kabul | I4: AFN | J4: Afghan afghani | K4: ؋ | L4: .af | M4: افغانستان | N4: Asia | O4: 3 | P4: Southern Asia | Q4: 14 | R4: Afghan | S4: 🇦🇫 | T4: U+1F1E6 U+1F1EB
A5: 1 | B5: 2 | C5: Aland Islands | D5: ALA | E5: AX | F5: 248 | G5: 358 | H5: Mariehamn | I5: EUR | J5: Euro | K5: € | L5: .ax | M5: Åland | N5: Europe | O5: 4 | P5: Northern Europe | Q5: 18 | R5: Aland Island | S5: 🇦🇽 | T5: U+1F1E6 U+1F1FD
A6: 2 | B6: 3 | C6: Albania | D6: ALB | E6: AL | F6: 8 | G6: 355 | H6: Tirana | I6: ALL | J6: Albanian lek | K6: Lek | L6: .al | M6: Shqipëria | N6: Europe | O6: 4 | P6: Southern Europe | Q6: 16 | R6: Albanian | S6: 🇦🇱 | T6: U+1F1E6 U+1F1F1
A7: 3 | B7: 4 | C7: Algeria | D7: DZA | E7: DZ | F7: 12 | G7: 213 | H7: Algiers | I7: DZD | J7: Algerian dinar | K7: دج | L7: .dz | M7: الجزائر | N7: Africa | O7: 1 | P7: Northern Africa | Q7: 1 | R7: Algerian | S7: 🇩🇿 | T7: U+1F1E9 U+1F1FF
A8: 4 | B8: 5 | C8: American Samoa | D8: ASM | E8: AS | F8: 16 | G8: 1 | H8: Pago Pago | I8: USD | J8: United States dollar | K8: $ | L8: .as | M8: American Samoa | N8: Oceania | O8: 5 | P8: Polynesia | Q8: 22 | R8: American Samoan | S8: 🇦🇸 | T8: U+1F1E6 U+1F1F8
A9: 5 | B9: 6 | C9: Andorra | D9: AND | E9: AD | F9: 20 | G9: 376 | H9: Andorra la Vella | I9: EUR | J9: Euro | K9: € | L9: .ad | M9: Andorra | N9: Europe | O9: 4 | P9: Southern Europe | Q9: 16 | R9: Andorran | S9: 🇦🇩 | T9: U+1F1E6 U+1F1E9
A10: 6 | B10: 7 | C10: Angola | D10: AGO | E10: AO | F10: 24 | G10: 244 | H10: Luanda | I10: AOA | J10: Angolan kwanza | K10: Kz | L10: .ao | M10: Angola | N10: Africa | O10: 1 | P10: Middle Africa | Q10: 2 | R10: Angolan | S10: 🇦🇴 | T10: U+1F1E6 U+1F1F4
A11: 7 | B11: 8 | C11: Anguilla | D11: AIA | E11: AI | F11: 660 | G11: 1 | H11: The Valley | I11: XCD | J11: Eastern Caribbean dollar | K11: $ | L11: .ai | M11: Anguilla | N11: Americas | O11: 2 | P11: Caribbean | Q11: 7 | R11: Anguillan | S11: 🇦🇮 | T11: U+1F1E6 U+1F1EE
A12: 8 | B12: 9 | C12: Antarctica | D12: ATA | E12: AQ | F12: 10 | G12: 672 | I12: AAD | J12: Antarctican dollar | K12: $ | L12: .aq | M12: Antarctica | N12: Polar | O12: 6 | R12: Antarctic | S12: 🇦🇶 | T12: U+1F1E6 U+1F1F6
A13: 9 | B13: 10 | C13: Antigua and Barbuda | D13: ATG | E13: AG | F13: 28 | G13: 1 | H13: St. John's | I13: XCD | J13: Eastern Caribbean dollar | K13: $ | L13: .ag | M13: Antigua and Barbuda | N13: Americas | O13: 2 | P13: Caribbean | Q13: 7 | R13: Antiguan or Barbudan | S13: 🇦🇬 | T13: U+1F1E6 U+1F1EC
A14: 10 | B14: 11 | C14: Argentina | D14: ARG | E14: AR | F14: 32 | G14: 54 | H14: Buenos Aires | I14: ARS | J14: Argentine peso | K14: $ | L14: .ar | M14: Argentina | N14: Americas | O14: 2 | P14: South America | Q14: 8 | R14: Argentine | S14: 🇦🇷 | T14: U+1F1E6 U+1F1F7
A15: 11 | B15: 12 | C15: Armenia | D15: ARM | E15: AM | F15: 51 | G15: 374 | H15: Yerevan | I15: AMD | J15: Armenian dram | K15: ֏ | L15: .am | M15: Հայաստան | N15: Asia | O15: 3 | P15: Western Asia | Q15: 11 | R15: Armenian | S15: 🇦🇲 | T15: U+1F1E6 U+1F1F2
A16: 12 | B16: 13 | C16: Aruba | D16: ABW | E16: AW | F16: 533 | G16: 297 | H16: Oranjestad | I16: AWG | J16: Aruban florin | K16: ƒ | L16: .aw | M16: Aruba | N16: Americas | O16: 2 | P16: Caribbean | Q16: 7 | R16: Aruban | S16: 🇦🇼 | T16: U+1F1E6 U+1F1FC
A17: 13 | B17: 14 | C17: Australia | D17: AUS | E17: AU | F17: 36 | G17: 61 | H17: Canberra | I17: AUD | J17: Australian dollar | K17: $ | L17: .au | M17: Australia | N17: Oceania | O17: 5 | P17: Australia and New Zealand | Q17: 19 | R17: Australian | S17: 🇦🇺 | T17: U+1F1E6 U+1F1FA
A18: 14 | B18: 15 | C18: Austria | D18: AUT | E18: AT | F18: 40 | G18: 43 | H18: Vienna | I18: EUR | J18: Euro | K18: € | L18: .at | M18: Österreich | N18: Europe | O18: 4 | P18: Western Europe | Q18: 17 | R18: Austrian | S18: 🇦🇹 | T18: U+1F1E6 U+1F1F9
A19: 15 | B19: 16 | C19: Azerbaijan | D19: AZE | E19: AZ | F19: 31 | G19: 994 | H19: Baku | I19: AZN | J19: Azerbaijani manat | K19: m | L19: .az | M19: Azərbaycan | N19: Asia | O19: 3 | P19: Western Asia | Q19: 11 | R19: Azerbaijani, Azeri | S19: 🇦🇿 | T19: U+1F1E6 U+1F1FF
A20: 16 | B20: 17 | C20: Bahrain | D20: BHR | E20: BH | F20: 48 | G20: 973 | H20: Manama | I20: BHD | J20: Bahraini dinar | K20: .د.ب | L20: .bh | M20: ‏البحرين | N20: Asia | O20: 3 | P20: Western Asia | Q20: 11 | R20: Bahraini | S20: 🇧🇭 | T20: U+1F1E7 U+1F1ED
A21: 17 | B21: 18 | C21: Bangladesh | D21: BGD | E21: BD | F21: 50 | G21: 880 | H21: Dhaka | I21: BDT | J21: Bangladeshi taka | K21: ৳ | L21: .bd | M21: Bangladesh | N21: Asia | O21: 3 | P21: Southern Asia | Q21: 14 | R21: Bangladeshi | S21: 🇧🇩 | T21: U+1F1E7 U+1F1E9
A22: 18 | B22: 19 | C22: Barbados | D22: BRB | E22: BB | F22: 52 | G22: 1 | H22: Bridgetown | I22: BBD | J22: Barbadian dollar | K22: Bds$ | L22: .bb | M22: Barbados | N22: Americas | O22: 2 | P22: Caribbean | Q22: 7 | R22: Barbadian | S22: 🇧🇧 | T22: U+1F1E7 U+1F1E7
A23: 19 | B23: 20 | C23: Belarus | D23: BLR | E23: BY | F23: 112 | G23: 375 | H23: Minsk | I23: BYN | J23: Belarusian ruble | K23: Br | L23: .by | M23: Белару́сь | N23: Europe | O23: 4 | P23: Eastern Europe | Q23: 15 | R23: Belarusian | S23: 🇧🇾 | T23: U+1F1E7 U+1F1FE
A24: 20 | B24: 21 | C24: Belgium | D24: BEL | E24: BE | F24: 56 | G24: 32 | H24: Brussels | I24: EUR | J24: Euro | K24: € | L24: .be | M24: België | N24: Europe | O24: 4 | P24: Western Europe | Q24: 17 | R24: Belgian | S24: 🇧🇪 | T24: U+1F1E7 U+1F1EA
... A32: 28 | B32: 29 | C32: Botswana | D32: BWA | E32: BW | F32: 72 | G32: 267 | H32: Gaborone | I32: BWP | J32: Botswana pula | K32: P | L32: .bw | M32: Botswana | N32: Africa | O32: 1 | P32: Southern Africa | Q32: 5 | R32: Motswana, Botswanan | S32: 🇧🇼 | T32: U+1F1E7 U+1F1FC
A33: 29 | B33: 30 | C33: Bouvet Island | D33: BVT | E33: BV | F33: 74 | G33: 55 | I33: NOK | J33: Norwegian krone | K33: ko | L33: .bv | M33: Bouvetøya | R33: Bouvet Island | S33: 🇧🇻 | T33: U+1F1E7 U+1F1FB
A34: 30 | B34: 31 | C34: Brazil | D34: BRA | E34: BR | F34: 76 | G34: 55 | H34: Brasilia | I34: BRL | J34: Brazilian real | K34: R$ | L34: .br | M34: Brasil | N34: Americas | O34: 2 | P34: South America | Q34: 8 | R34: Brazilian | S34: 🇧🇷 | T34: U+1F1E7 U+1F1F7
A35: 31 | B35: 32 | C35: British Indian Ocean Territory | D35: IOT | E35: IO | F35: 86 | G35: 246 | H35: Diego Garcia | I35: USD | J35: United States dollar | K35: $ | L35: .io | M35: British Indian Ocean Territory | N35: Africa | O35: 1 | P35: Eastern Africa | Q35: 4 | R35: BIOT | S35: 🇮🇴 | T35: U+1F1EE U+1F1F4
A36: 32 | B36: 33 | C36: Brunei | D36: BRN | E36: BN | F36: 96 | G36: 673 | H36: Bandar Seri Begawan | I36: BND | J36: Brunei dollar | K36: B$ | L36: .bn | M36: Negara Brunei Darussalam | N36: Asia | O36: 3 | P36: South-Eastern Asia | Q36: 13 | R36: Bruneian | S36: 🇧🇳 | T36: U+1F1E7 U+1F1F3
A37: 33 | B37: 34 | C37: Bulgaria | D37: BGR | E37: BG | F37: 100 | G37: 359 | H37: Sofia | I37: BGN | J37: Bulgarian lev | K37: Лв. | L37: .bg | M37: България | N37: Europe | O37: 4 | P37: Eastern Europe | Q37: 15 | R37: Bulgarian | S37: 🇧🇬 | T37: U+1F1E7 U+1F1EC
A38: 34 | B38: 35 | C38: Burkina Faso | D38: BFA | E38: BF | F38: 854 | G38: 226 | H38: Ouagadougou | I38: XOF | J38: West African CFA franc | K38: CFA | L38: .bf | M38: Burkina Faso | N38: Africa | O38: 1 | P38: Western Africa | Q38: 3 | R38: Burkinabe | S38: 🇧🇫 | T38: U+1F1E7 U+1F1EB
A39: 35 | B39: 36 | C39: Burundi | D39: BDI | E39: BI | F39: 108 | G39: 257 | H39: Bujumbura | I39: BIF | J39: Burundian franc | K39: FBu | L39: .bi | M39: Burundi | N39: Africa | O39: 1 | P39: Eastern Africa | Q39: 4 | R39: Burundian | S39: 🇧🇮 | T39: U+1F1E7 U+1F1EE
A40: 36 | B40: 37 | C40: Cambodia | D40: KHM | E40: KH | F40: 116 | G40: 855 | H40: Phnom Penh | I40: KHR | J40: Cambodian riel | K40: KHR | L40: .kh | M40: Kâmpŭchéa | N40: Asia | O40: 3 | P40: South-Eastern Asia | Q40: 13 | R40: Cambodian | S40: 🇰🇭 | T40: U+1F1F0 U+1F1ED
A41: 37 | B41: 38 | C41: Cameroon | D41: CMR | E41: CM | F41: 120 | G41: 237 | H41: Yaounde | I41: XAF | J41: Central African CFA franc | K41: FCFA | L41: .cm | M41: Cameroon | N41: Africa | O41: 1 | P41: Middle Africa | Q41: 2 | R41: Cameroonian | S41: 🇨🇲 | T41: U+1F1E8 U+1F1F2
A42: 38 | B42: 39 | C42: Canada | D42: CAN | E42: CA | F42: 124 | G42: 1 | H42: Ottawa | I42: CAD | J42: Canadian dollar | K42: $ | L42: .ca | M42: Canada | N42: Americas | O42: 2 | P42: Northern America | Q42: 6 | R42: Canadian | S42: 🇨🇦 | T42: U+1F1E8 U+1F1E6
A43: 39 | B43: 40 | C43: Cape Verde | D43: CPV | E43: CV | F43: 132 | G43: 238 | H43: Praia | I43: CVE | J43: Cape Verdean escudo | K43: $ | L43: .cv | M43: Cabo Verde | N43: Africa | O43: 1 | P43: Western Africa | Q43: 3 | R43: Verdean | S43: 🇨🇻 | T43: U+1F1E8 U+1F1FB
A44: 40 | B44: 41 | C44: Cayman Islands | D44: CYM | E44: KY | F44: 136 | G44: 1 | H44: George Town | I44: KYD | J44: Cayman Islands dollar | K44: $ | L44: .ky | M44: Cayman Islands | N44: Americas | O44: 2 | P44: Caribbean | Q44: 7 | R44: Caymanian | S44: 🇰🇾 | T44: U+1F1F0 U+1F1FE
A45: 41 | B45: 42 | C45: Central African Republic | D45: CAF | E45: CF | F45: 140 | G45: 236 | H45: Bangui | I45: XAF | J45: Central African CFA franc | K45: FCFA | L45: .cf | M45: Ködörösêse tî Bêafrîka | N45: Africa | O45: 1 | P45: Middle Africa | Q45: 2 | R45: Central African | S45: 🇨🇫 | T45: U+1F1E8 U+1F1EB
... A55: 51 | B55: 52 | C55: Costa Rica | D55: CRI | E55: CR | F55: 188 | G55: 506 | H55: San Jose | I55: CRC | J55: Costa Rican colón | K55: ₡ | L55: .cr | M55: Costa Rica | N55: Americas | O55: 2 | P55: Central America | Q55: 9 | R55: Costa Rican | S55: 🇨🇷 | T55: U+1F1E8 U+1F1F7
A56: 52 | B56: 53 | C56: Cote D'Ivoire (Ivory Coast) | D56: CIV | E56: CI | F56: 384 | G56: 225 | H56: Yamoussoukro | I56: XOF | J56: West African CFA franc | K56: CFA | L56: .ci | N56: Africa | O56: 1 | P56: Western Africa | Q56: 3 | R56: Ivorian | S56: 🇨🇮 | T56: U+1F1E8 U+1F1EE
...

Sheet SaveToDB_UpdatedID
A1: ID
A2: Start IDs of object [dbo.studios] on sheet [studios]
A3: 194
A4: End IDs of object [dbo.studios] on sheet [studios]

Sheet SaveToDB_Lists
A1: ID
